<?xml version="1.0"?>
<robot name="omni_robot">

  <!-- BASE -->
  <link name="base_link">
    <visual>
      <geometry>
        <cylinder radius="0.2" length="0.1"/>
      </geometry>
    </visual>
  </link>

  <!-- WHEEL 1 -->
  <link name="wheel1">
    <visual>
      <geometry>
        <cylinder radius="0.08" length="0.02"/>
      </geometry>
    </visual>
  </link>

  <joint name="wheel1_joint" type="continuous">
    <parent link="base_link"/>
    <child link="wheel1"/>
    <origin xyz="0.2 0 0" rpy="0 1.57 0"/>
    <axis xyz="0 0 1"/>
  </joint>

  <!-- WHEEL 2 -->
  <link name="wheel2">
    <visual>
      <geometry>
        <cylinder radius="0.08" length="0.02"/>
      </geometry>
    </visual>
  </link>

  <joint name="wheel2_joint" type="continuous">
    <parent link="base_link"/>
    <child link="wheel2"/>
    <origin xyz="-0.1 0.173 0" rpy="0 1.57 0"/>
    <axis xyz="0 0 1"/>
  </joint>

  <!-- WHEEL 3 -->
  <link name="wheel3">
    <visual>
      <geometry>
        <cylinder radius="0.08" length="0.02"/>
      </geometry>
    </visual>
  </link>

  <joint name="wheel3_joint" type="continuous">
    <parent link="base_link"/>
    <child link="wheel3"/>
    <origin xyz="-0.1 -0.173 0" rpy="0 1.57 0"/>
    <axis xyz="0 0 1"/>
  </joint>

</robot>
